Workbook

Sheet README
A1: 서울 자치구 월세 리스크 변수 통합 데이터사전
A2: 목적 | B2: 세 명의 데이터사전을 통합하되 어떤 변수도 삭제하지 않고, 6개 동인 기준으로 1차/2차 분류한 마스터 템플릿
A3: 총 원본 변수/자료행 | B3: 77 | C3: 원칙 | D3: 중복·유사변수도 모두 보존
A4: 6개 동인 | B4: ① 임차수요 압력 / ② 주택공급·재고 여건 / ③ 금융여건·상대가격 / ④ 임대시장 수급·전환 구조 / ⑤ 시장과열·단기 트리거 / ⑥ 거시경기·금융시장 여건
A5: 분류 구조 | B5: ①~④ = 지역/구조적 취약성, ⑤ = 단기 트리거, ⑥ = 공통 거시환경
A6: 중요 | B6: 월세가격지수 등 종속변수 후보는 삭제하지 않고 ⑤에 보존하되, 동일월 설명변수 사용 시 leakage 위험을 '높음'으로 표시
A7: 시점관리 | B7: reference period와 release/available date를 분리하고, 실제 예측시점에 가용했던 값만 사용
A8: 향후 절차 | B8: 전체 변수 보존 → 공표시차/공간단위 정비 → 파생변수 생성 → OOS 검증 → 중요도/중복성 기준으로 후순위에서 선별

Sheet 동인분류_가이드
A1: 동인 | B1: 구조적 위치 | C1: 핵심 질문 | D1: 주요 하위영역 | E1: 대표 예시 | F1: 분류 원칙
A2: ① 임차수요 압력 | B2: Local Vulnerability | C2: 해당 지역의 임차수요가 얼마나 증가하는가? | D2: 인구·세대·연령·이동·고용·소득 | E2: 세대수, 청년인구, 순이동, 지역 고용/소득 | F2: 지역별 수요의 기초 펀더멘털이면 ①
A3: ② 주택공급·재고 여건 | B3: Local Vulnerability | C3: 늘어나는 수요를 주택공급이 흡수할 수 있는가? | D3: 재고·인허가·착공·준공·미분양·임대주택 | E3: 준공, 착공, 미분양, 주택수 | F3: 물리적 주택 공급·재고면 ②
A4: ③ 금융여건·상대가격 | B4: Local Vulnerability | C4: 주거 선택의 금융비용과 상대가격이 어떻게 변하는가? | D4: 주담대·전세대출·매매/전세가격·전세가율·전환율 | E4: 주담대금리, 전세대출금리, 전세가율 | F4: 주택금융·매매/전세/월세 상대비용이면 ③
A5: ④ 임대시장 수급·전환 구조 | B5: Local Vulnerability / Transmission | C5: 펀더멘털이 실제 임대계약 구성에 어떻게 나타나는가? | D5: 월세비중·전세수급·월세수급·실거래 구성 | E5: 전월세 실거래, 월세수급지수 | F5: 임대계약 수급·전환·구성변화면 ④
A6: ⑤ 시장과열·단기 트리거 | B6: Near-term Trigger | C6: 급등 직전 가격·거래·심리의 이상 신호가 있는가? | D6: 가격 모멘텀·변동성·심리·거래 shock | E6: 월세가격 모멘텀, 주택가격전망CSI | F6: 단기 가속/충격/심리 신호면 ⑤
A7: ⑥ 거시경기·금융시장 여건 | B7: Common Macro State | C7: 전 자치구에 공통인 경기·금융 국면은 어떤가? | D7: 정책금리·시장금리·유동성·주가·경기·물가 | E7: 기준금리, KOSPI, M2, CPI, 선행지수 | F7: 전국 공통 거시·금융 변수면 ⑥

Sheet Variable_Master
A1: Master ID | B1: 수집자 | C1: 원본파일 | D1: 원본시트 | E1: 원본행 | F1: 원분류 | G1: 원ID | H1: 변수명 | I1: 1차 동인 | J1: 2차 동인 | K1: 변수 역할 | L1: 정보유형 | M1: 예상 부호 | N1: 기대 선행성 | O1: Leakage Risk | P1: 권장 가공/파생변수 | Q1: 삭제 | R1: 수록기간 | S1: 빈도 | T1: 발표·가용 시점 | U1: 지역 범위 | V1: 서울25구 | W1: 17개시도 | X1: 출처기관 | Y1: 표ID/CODE | Z1: 공식 URL | AA1: 현재 파일 | AB1: 원본 주의사항 | AC1: 보완 근거 | AD1: 정보 보완 필요 | AE1: 중복/유사 표시 | AF1: 보존 여부 | AG1: 초기 활용상태 | AH1: 분류 비고 | AI1: 분류 근거
A2: V009 | B2: 권태혁 | C2: 260919_데이터사전_권태혁.xlsx | D2: 변수현황 | E2: 14 | F2: 수요 | G2: D1 | H2: 주민등록 인구 | I2: ① 임차수요 압력 | K2: 설명변수 후보 | L2: Structural/Flow | M2: + | N2: 1~12개월 | O2: 낮음 | P2: YoY, 3M/12M 변화, 인구·세대 대비 | R2: 2011.01–2026.08 | S2: 월 | T2: 기준월 익월 1일 전후 | U2: 17개 시도·서울 25개 구 | V2: Y | W2: Y | X2: 행정안전부 | Y2: 주민등록인구통계 | Z2: https://jumin.mois.go.kr/statMonth.do | AB2: 행안부 월말 인구. 광주·전남 행정구역 변경 시기 확인 / 주민등록 기준, 외국인 제외 | AC2: 행안부 주민등록 월말 통계 | AF2: 보존(삭제 안 함) | AG2: 후보 유지 | AI2: 지역별 인구·가구·이동·고용·소득 등 임차수요의 기초 펀더멘털을 측정
A3: V010 | B3: 권태혁 | C3: 260919_데이터사전_권태혁.xlsx | D3: 변수현황 | E3: 15 | F3: 수요 | G3: D2 | H3: 주민등록 세대수 | I3: ① 임차수요 압력 | K3: 설명변수 후보 | L3: Structural/Flow | M3: + | N3: 1~12개월 | O3: 낮음 | P3: YoY, 3M/12M 변화, 인구·세대 대비 | R3: 2011.01–2026.08 | S3: 월 | T3: 기준월 익월 1일 전후 | U3: 17개 시도·서울 25개 구 | V3: Y | W3: Y | X3: 행정안전부 | Y3: 주민등록인구통계 | Z3: https://jumin.mois.go.kr/statMonth.do | AB3: D1과 같은 원자료에서 추출 / 주민등록 기준, 외국인 제외 | AC3: 행안부 주민등록 월말 통계 | AE3: 유사/중복군_주민등록세대수 | AF3: 보존(삭제 안 함) | AG3: 후보 유지 | AI3: 지역별 인구·가구·이동·고용·소득 등 임차수요의 기초 펀더멘털을 측정
A4: V011 | B4: 권태혁 | C4: 260919_데이터사전_권태혁.xlsx | D4: 변수현황 | E4: 16 | F4: 수요 | G4: D3 | H4: 20–29세·30–39세 인구 | I4: ① 임차수요 압력 | K4: 설명변수 후보 | L4: Structural/Flow | M4: + | N4: 1~12개월 | O4: 낮음 | P4: YoY, 3M/12M 변화, 인구·세대 대비 | R4: 2011.01–2026.08 | S4: 월 | T4: 기준월 익월 1일 전후 | U4: 17개 시도·서울 25개 구 | V4: Y | W4: Y | X4: 행정안전부 | Y4: 연령별인구현황 | Z4: https://jumin.mois.go.kr/ageStatMonth.do | AB4: 연령대 인원과 20–39세 비중(계산값)을 함께 수록 / 20대·30대와 합계 비중 | AC4: 행안부 주민등록 월말 통계 | AF4: 보존(삭제 안 함) | AG4: 후보 유지 | AI4: 지역별 인구·가구·이동·고용·소득 등 임차수요의 기초 펀더멘털을 측정
A5: V012 | B5: 권태혁 | C5: 260919_데이터사전_권태혁.xlsx | D5: 변수현황 | E5: 17 | F5: 수요 | G5: D4 | H5: 순이동자수 | I5: ① 임차수요 압력 | K5: 설명변수 후보 | L5: Structural/Flow | M5: + | N5: 1~12개월 | O5: 낮음 | P5: YoY, 3M/12M 변화, 인구·세대 대비 | R5: 2011.01–2026.07 | S5: 월 | T5: 통상 익월 말 전후 | U5: 17개 시도·서울 25개 구 | V5: Y | W5: Y | X5: KOSIS 국내인구이동통계 | Y5: 101/DT_1B26001_A01 | Z5: https://kosis.kr/statHtml/statHtml.do?orgId=101&tblId=DT_1B26001_A01&conn_path=I2 | AB5: KOSIS 월별 시군구 이동 통계. 최신 발표월은 2026.07 / 시도·서울 구별 순이동 | AC5: KOSIS 국내인구이동 월별 통계 | AF5: 보존(삭제 안 함) | AG5: 후보 유지 | AI5: 지역별 인구·가구·이동·고용·소득 등 임차수요의 기초 펀더멘털을 측정
A6: V013 | B6: 권태혁 | C6: 260919_데이터사전_권태혁.xlsx | D6: 변수현황 | E6: 18 | F6: 수요 | G6: D5 | H6: 고용률·취업자 | I6: ① 임차수요 압력 | K6: 설명변수 후보 | L6: Structural/Flow | M6: + | N6: 1~12개월 | O6: 낮음 | P6: YoY, 3M/12M 변화, 인구·세대 대비 | R6: 시도 2011.01~ / 구 2021H1~ | S6: 월/반기 | T6: 시도 월별: 익월 중순 / 서울 구 반기: 4월조사→8월, 10월조사→익년 2월 | U6: 시도 월별·서울 구 반기 | V6: N | X6: KOSIS 경제활동인구조사·지역별고용조사 | Y6: DT_1DA7004S / DT_1ES3A01S | Z6: https://kosis.kr/statHtml/statHtml.do?orgId=101&tblId=DT_1DA7004S&conn_path=I2 | AB6: 서울 구 고용은 반기표에 별도 보관. 월별로 복제하지 않음 / 시도 월별, 서울 구 반기 | AC6: 노경수 데이터사전 지역별고용조사 일정 | AF6: 보존(삭제 안 함) | AG6: 후보 유지 | AI6: 지역별 인구·가구·이동·고용·소득 등 임차수요의 기초 펀더멘털을 측정
A7: V015 | B7: 권태혁 | C7: 260919_데이터사전_권태혁.xlsx | D7: 변수현황 | E7: 20 | F7: 수요 | G7: D7 | H7: 1인당 GRDP | I7: ① 임차수요 압력 | K7: 설명변수 후보 | L7: Structural/Flow | M7: + | N7: 1~12개월 | O7: 낮음 | P7: YoY, 3M/12M 변화, 인구·세대 대비 | R7: 2011–2024 연간 | S7: 년 | T7: 연간 공표; 공표시차가 길어 available_date 별도 관리 | U7: 17개 시도 | V7: N | W7: Y | X7: KOSIS 지역소득 | Y7: 101/DT_1C96 | Z7: https://kosis.kr/statHtml/statHtml.do?orgId=101&tblId=DT_1C96&conn_path=I2 | AB7: 지역 생산 지표. 단위 천원 / 각각 천원 | AC7: 연간 지역소득/국세통계 특성 | AF7: 보존(삭제 안 함) | AG7: 후보 유지 | AI7: 지역별 인구·가구·이동·고용·소득 등 임차수요의 기초 펀더멘털을 측정
A8: V017 | B8: 권태혁 | C8: 260919_데이터사전_권태혁.xlsx | D8: 변수현황 | E8: 22 | F8: 수요 | G8: D9 | H8: 1인당 가계총처분가능소득 | I8: ① 임차수요 압력 | K8: 설명변수 후보 | L8: Structural/Flow | M8: + | N8: 1~12개월 | O8: 낮음 | P8: YoY, 3M/12M 변화, 인구·세대 대비 | R8: 2011–2024 연간 | S8: 년 | T8: 연간 공표; 공표시차가 길어 available_date 별도 관리 | U8: 17개 시도 | V8: N | W8: Y | X8: KOSIS 지역소득 | Y8: 101/DT_1C96 | Z8: https://kosis.kr/statHtml/statHtml.do?orgId=101&tblId=DT_1C96&conn_path=I2 | AB8: 가계 처분가능소득. 단위 천원 / 각각 천원 | AC8: 연간 지역소득/국세통계 특성 | AF8: 보존(삭제 안 함) | AG8: 후보 유지 | AI8: 지역별 인구·가구·이동·고용·소득 등 임차수요의 기초 펀더멘털을 측정
A9: V021 | B9: 권태혁 | C9: 260919_데이터사전_권태혁.xlsx | D9: 변수현황 | E9: 26 | F9: 공급 | G9: S4 | H9: 아파트 인허가 호수 | I9: ② 주택공급·재고 여건 | K9: 설명변수 후보 | L9: Structural/Flow | M9: - | N9: 3~36개월 | O9: 낮음 | P9: 인구·세대 대비, 3M/12M 누적, 추세 대비 gap | R9: 2011.01–2026.07 | S9: 월 | T9: 기준월 익월 말 전후 | U9: 17개 시도 | V9: N | W9: Y | X9: KOSIS 주택건설실적통계 | Y9: 116/DT_MLTM_1948 | Z9: https://kosis.kr/statHtml/statHtml.do?orgId=116&tblId=DT_MLTM_1948&conn_path=I2 | AB9: 공식 연초누계 값을 월별 차분으로 변환. 원응답 보관 / 원자료 연초 누계, 월 차분으로 변환 | AC9: 국토부 월간 주택통계 | AF9: 보존(삭제 안 함) | AG9: 후보 유지 | AI9: 주택의 물리적 재고와 신규 공급·미분양 등 공급 흡수력을 측정
A10: V022 | B10: 권태혁 | C10: 260919_데이터사전_권태혁.xlsx | D10: 변수현황 | E10: 27 | F10: 공급 | G10: S5 | H10: 아파트 착공 호수 | I10: ② 주택공급·재고 여건 | K10: 설명변수 후보 | L10: Structural/Flow | M10: - | N10: 3~36개월 | O10: 낮음 | P10: 인구·세대 대비, 3M/12M 누적, 추세 대비 gap | R10: 2011.01–2026.07 | S10: 월 | T10: 기준월 익월 말 전후 | U10: 17개 시도 | V10: N | W10: Y | X10: KOSIS 주택건설실적통계 | Y10: 116/DT_MLTM_5387 | Z10: https://kosis.kr/statHtml/statHtml.do?orgId=116&tblId=DT_MLTM_5387&conn_path=I2 | AB10: 아파트 전용. 일부 지역·월 공란은 결측으로 유지 / 아파트 호수 | AC10: 국토부 월간 주택통계 | AF10: 보존(삭제 안 함) | AG10: 후보 유지 | AI10: 주택의 물리적 재고와 신규 공급·미분양 등 공급 흡수력을 측정
A11: V023 | B11: 권태혁 | C11: 260919_데이터사전_권태혁.xlsx | D11: 변수현황 | E11: 28 | F11: 공급 | G11: S6 | H11: 아파트 준공 호수 | I11: ② 주택공급·재고 여건 | K11: 설명변수 후보 | L11: Structural/Flow | M11: - | N11: 3~36개월 | O11: 낮음 | P11: 인구·세대 대비, 3M/12M 누적, 추세 대비 gap | R11: 2011.01–2026.07 | S11: 월 | T11: 기준월 익월 말 전후 | U11: 17개 시도 | V11: N | W11: Y | X11: KOSIS 주택건설실적통계 | Y11: 116/DT_MLTM_5373 | Z11: https://kosis.kr/statHtml/statHtml.do?orgId=116&tblId=DT_MLTM_5373&conn_path=I2 | AB11: 아파트 전용. 일부 지역·월 공란은 결측으로 유지 / 아파트 호수 | AC11: 국토부 월간 주택통계 | AF11: 보존(삭제 안 함) | AG11: 후보 유지 | AI11: 주택의 물리적 재고와 신규 공급·미분양 등 공급 흡수력을 측정
A12: V024 | B12: 권태혁 | C12: 260919_데이터사전_권태혁.xlsx | D12: 변수현황 | E12: 29 | F12: 공급 | G12: S7 | H12: 서울 구 주거용 신축허가 | I12: ② 주택공급·재고 여건 | K12: 설명변수 후보 | L12: Structural/Flow | M12: - | N12: 3~36개월 | O12: 낮음 | P12: 인구·세대 대비, 3M/12M 누적, 추세 대비 gap | R12: 2011–2024 연간 | S12: 년 | T12: 연간 공표; 실제 공표일 별도 확인 | U12: 서울 25개 구 | V12: Y | X12: KOSIS 서울통계 | Y12: 201/DT_201004_O090005 | Z12: https://stat.eseoul.go.kr/statHtml/statHtml.do?orgId=201&tblId=DT_201004_O090005&conn_path=I2 | AB12: 동수·연면적(㎡). 아파트 세대수와 같지 않음 / 동수·㎡, 아파트 호수 아님 | AC12: 서울통계 연간자료 | AF12: 보존(삭제 안 함) | AG12: 후보 유지 | AI12: 주택의 물리적 재고와 신규 공급·미분양 등 공급 흡수력을 측정
A13: V038 | B13: 노경수 | C13: 260919_데이터사전_노경수.xlsx | D13: 데이터목록 | E13: 15 | F13: 공급·재고 | H13: 미분양주택현황 | I13: ② 주택공급·재고 여건 | K13: 설명변수 후보 | L13: Structural/Flow | M13: ± | N13: 3~36개월 | O13: 낮음 | P13: 인구·세대 대비, 3M/12M 누적, 추세 대비 gap | R13: 2007-01 ~ 2026-07 | S13: 월간 | T13: 국토교통부 월간 주택통계로 기준월 익월 말(최근 2026-07분 8/31 06:00) 공표. | U13: 17개 시도 + 서울 25개 자치구(서울시 합계 포함). 세종은 2012-07부터. | V13: Y | W13: 조건부 | X13: 국토교통부/공공데이터포털 | Z13: https://www.molit.go.kr/USR/NEWS/m_71/dtl.jsp?id=95092360 | AA13: 부동산원_미분양주택현황.csv | AB13: 현재 파일에서 광주·전남은 2026-06까지만 있고 타 지역은 2026-07까지 있어 최신월 비대칭. 월별 패널 병합 전 지역별 최신월 일치 여부 검사 필요. | AF13: 보존(삭제 안 함) | AG13: 후보 유지 | AI13: 주택의 물리적 재고와 신규 공급·미분양 등 공급 흡수력을 측정
A14: V072 | B14: 박준우 | C14: 260919_데이터사전_박준우.xlsx | D14: Sheet1 | E14: 23 | F14: 참고 | H14: 서울시 및 구별 가구 및 주택 수 | I14: ② 주택공급·재고 여건 | J14: ① 임차수요 압력 | K14: 설명변수 후보 | L14: Structural | M14: ± | N14: 구조적 | O14: 낮음 | P14: 주택수/가구수, 가구증가율, 재고증가율 | R14: 42369 | S14: 연간 | T14: 익년 8월 | U14: 서울시 및 25개 자치구 | V14: Y | X14: KOSIS/해당 작성기관 | Z14: https://kosis.kr/ | AB14: 인구 - 인구부문 - 총조사인구(2015년 이후) - 전수부문 - 전수 기본표 - 인구, 가구 및 주택 – 읍면동(연도 끝자리 0, 5), 시군구(그 외 연도) | AC14: 지표명/참고 설명 기준 | AF14: 보존(삭제 안 함) | AG14: 후보 유지 | AI14: 주택의 물리적 재고와 신규 공급·미분양 등 공급 흡수력을 측정 / 보조적으로 ① 임차수요 압력 성격도 존재
A15: V076 | B15: 박준우 | C15: 260919_데이터사전_박준우.xlsx | D15: Sheet1 | E15: 27 | H15: 임대주택공급현황 | I15: ② 주택공급·재고 여건 | K15: 설명변수 후보 | L15: Structural/Flow | M15: - | N15: 3~36개월 | O15: 낮음 | P15: 인구·세대 대비, 3M/12M 누적, 추세 대비 gap | R15: 2020~2024 | S15: 연간 | T15: 익년 10월 | U15: 지역단위 원표 확인 필요 | X15: 국토교통부/KOSIS | Z15: https://kosis.kr/civilComplaint/qnaDetail.do?boardIdx=21575 | AC15: KOSIS 공식 Q&A에서 임대주택통계 작성·공표 체계 확인 | AF15: 보존(삭제 안 함) | AG15: 후보 유지 | AI15: 주택의 물리적 재고와 신규 공급·미분양 등 공급 흡수력을 측정
A16: V077 | B16: 박준우 | C16: 260919_데이터사전_박준우.xlsx | D16: Sheet1 | E16: 28 | H16: 임대주택건설공급현황 | I16: ② 주택공급·재고 여건 | K16: 설명변수 후보 | L16: Structural/Flow | M16: - | N16: 3~36개월 | O16: 낮음 | P16: 인구·세대 대비, 3M/12M 누적, 추세 대비 gap | R16: 2012~2019 | S16: 연간 | T16: 익년 10월 | U16: 지역단위 원표 확인 필요 | X16: 국토교통부/KOSIS | Z16: https://kosis.kr/civilComplaint/qnaDetail.do?boardIdx=21575 | AC16: KOSIS 공식 Q&A에서 2012~2019 임대주택건설공급현황 및 2020년 이후 분류체계 변경 확인 | AF16: 보존(삭제 안 함) | AG16: 후보 유지 | AI16: 주택의 물리적 재고와 신규 공급·미분양 등 공급 흡수력을 측정
A17: V002 | B17: 권태혁 | C17: 260919_데이터사전_권태혁.xlsx | D17: 변수현황 | E17: 7 | F17: 가격 | G17: P2 | H17: 아파트 매매가격지수 | I17: ③ 금융여건·상대가격 | K17: 설명변수 후보 | L17: Financial/Relative Price | M17: ± | N17: 0~12개월 | O17: 낮음 | P17: Level, 3M/12M 변화, spread/ratio | R17: 2011.01–2026.08 | S17: 월 | T17: 기준월 익월 15일 전후 | U17: 17개 시도·서울 25개 구 | V17: Y | W17: Y | X17: 한국부동산원 R-ONE | Y17: A_2024_00045 | Z17: https://www.reb.or.kr/r-one/portal/stat/easyStatPage/A_2024_00045.do | AB17: R-ONE 지수. 실거래 매매가격 수준과 다른 개념 / 가격 수준이 아니라 지수 | AC17: 노경수 데이터사전의 동일/유사 통계 | AE17: 유사/중복군_매매가격지수 | AF17: 보존(삭제 안 함) | AG17: 후보 유지 | AI17: 매매·전세·월세 선택에 영향을 주는 주택금융비용과 상대가격을 측정
A18: V003 | B18: 권태혁 | C18: 260919_데이터사전_권태혁.xlsx | D18: 변수현황 | E18: 8 | F18: 가격 | G18: P3 | H18: 아파트 전세가율 | I18: ③ 금융여건·상대가격 | K18: 설명변수 후보 | L18: Financial/Relative Price | M18: ± | N18: 0~12개월 | O18: 낮음 | P18: Level, 3M/12M 변화, spread/ratio | R18: 2012.01–2026.08 | S18: 월 | T18: 월간 공표; 실제 공표일 별도 관리 권장 | U18: 17개 시도·서울 25개 구 | V18: Y | W18: Y | X18: 한국부동산원 R-ONE | Y18: A_2024_00072 | Z18: https://www.reb.or.kr/r-one/portal/stat/easyStatPage/A_2024_00072.do | AB18: 매매가격 대비 전세가격 비율(%). 지역별 시작월 확인 / 매매가격 대비 전세가격 비율(%) | AC18: R-ONE 월간 통계 특성 | AF18: 보존(삭제 안 함) | AG18: 후보 유지 | AI18: 매매·전세·월세 선택에 영향을 주는 주택금융비용과 상대가격을 측정
A19: V004 | B19: 권태혁 | C19: 260919_데이터사전_권태혁.xlsx | D19: 변수현황 | E19: 9 | F19: 가격 | G19: P4 | H19: 아파트 전월세전환율 | I19: ③ 금융여건·상대가격 | J19: ④ 임대시장 수급·전환 구조 | K19: 설명변수 후보 | L19: Financial/Relative Price | M19: ± | N19: 0~12개월 | O19: 낮음 | P19: Level, 3M/12M 변화, spread/ratio | R19: 2011.01–2026.07 | S19: 월 | T19: 통상 익익월 15일(가격지수보다 1개월 추가 시차) | U19: 17개 시도·서울 25개 구 | V19: Y | W19: Y | X19: 한국부동산원 R-ONE | Y19: A_2024_00156 | Z19: https://www.reb.or.kr/r-one/portal/stat/easyStatPage/A_2024_00156.do | AB19: 일부 지역의 시작월이 다르고 최신 발표월은 2026.07 / 시도·구 일부 시작월 다름 | AC19: 노경수 데이터사전의 동일 통계 | AE19: 유사/중복군_전월세전환율 | AF19: 보존(삭제 안 함) | AG19: 후보 유지 | AI19: 매매·전세·월세 선택에 영향을 주는 주택금융비용과 상대가격을 측정 / 보조적으로 ④ 임대시장 수급·전환 구조 성격도 존재
A20: V007 | B20: 권태혁 | C20: 260919_데이터사전_권태혁.xlsx | D20: 변수현황 | E20: 12 | F20: 가격 | G20: P7 | H20: 아파트 매매 실거래 원본 | I20: ③ 금융여건·상대가격 | J20: ⑤ 시장과열·단기 트리거 | K20: 설명변수 후보 | L20: Financial/Relative Price | M20: ± | N20: 0~12개월 | O20: 낮음 | P20: Level, 3M/12M 변화, spread/ratio | R20: 2011.01–2026.08 | S20: 건 | T20: API/신고자료 수시 갱신; 월 집계 시 신고·정정 시차 고려 | U20: 서울 25개 구 | V20: Y | X20: 국토교통부 | Y20: RTMSDataSvcAptTrade | Z20: https://www.data.go.kr/data/15126469/openapi.do | AB20: 17개 시도 원본은 아직 미수집. 원본 행수는 공식 거래량 아님 / 계약 신고 원본. 해제·정정 가능 | AC20: 실거래 신고자료 특성 | AF20: 보존(삭제 안 함) | AG20: 후보 유지 | AI20: 매매·전세·월세 선택에 영향을 주는 주택금융비용과 상대가격을 측정 / 보조적으로 ⑤ 시장과열·단기 트리거 성격도 존재
A21: V026 | B21: 노경수 | C21: 260919_데이터사전_노경수.xlsx | D21: 데이터목록 | E21: 3 | F21: 주택가격 | H21: 아파트 전세가격지수 | I21: ③ 금융여건·상대가격 | K21: 설명변수 후보 | L21: Financial/Relative Price | M21: + | N21: 0~12개월 | O21: 낮음 | P21: Level, 3M/12M 변화, spread/ratio | R21: 2003-11 ~ 2026-08 | S21: 월간 | T21: 기준월 익월 15일(휴일이면 다음날) | U21: 17개 시도 + 서울 25개 자치구(서울시 합계 포함). 세종은 후발 편입. | V21: Y | W21: 조건부 | X21: 한국부동산원 | Z21: https://www.reb.or.kr/reb/cm/cntnts/cntntsView.do?cntntsId=1033&mi=10333&statId=S234820263 | AA21: 부동산원_가격지수_아파트.csv | AB21: 현재 기준 2026.6=100 재기준화. 표본조사 지수이므로 개별 계약가격과 다름. 장기패널에서 세종 시작시점 차이 처리 필요. | AF21: 보존(삭제 안 함) | AG21: 후보 유지 | AI21: 매매·전세·월세 선택에 영향을 주는 주택금융비용과 상대가격을 측정
A22: V031 | B22: 노경수 | C22: 260919_데이터사전_노경수.xlsx | D22: 데이터목록 | E22: 8 | F22: 시장수급 | H22: 아파트 매매수급동향지수 | I22: ③ 금융여건·상대가격 | J22: ⑤ 시장과열·단기 트리거 | K22: 설명변수 후보 | L22: Market Signal | M22: + | N22: 0~6개월 | O22: 낮음 | P22: 100 대비 gap, 3M 변화, z-score | R22: 2012-07 ~ 2026-08 | S22: 월간 | T22: 기준월 익월 15일(전국주택가격동향조사와 함께 공표) | U22: 17개 시도(서울 포함) 시도단위만. 서울 자치구 없음. 세종은 2012-12부터. | V22: N | W22: 조건부 | X22: 한국부동산원 | Z22: https://www.reb.or.kr/reb/cm/cntnts/cntntsView.do?cntntsId=1033&mi=10333&statId=S234820263 | AA22: 부동산원_수급동향_아파트.csv | AB22: 설문·표본 기반 체감 수급지수로 실제 거래량과 개념이 다름. 100 기준 해석과 조사개편 이력 확인 필요. 서울 자치구 분석에는 사용 불가. | AF22: 보존(삭제 안 함) | AG22: 후보 유지 | AI22: 매매·전세·월세 선택에 영향을 주는 주택금융비용과 상대가격을 측정 / 보조적으로 ⑤ 시장과열·단기 트리거 성격도 존재
A23: V036 | B23: 노경수 | C23: 260919_데이터사전_노경수.xlsx | D23: 데이터목록 | E23: 13 | F23: 거래 | H23: 행정구역별 아파트 매매거래현황(동·호수, 면적) | I23: ③ 금융여건·상대가격 | J23: ⑤ 시장과열·단기 트리거 | K23: 설명변수 후보 | L23: Financial/Relative Price | M23: ± | N23: 0~12개월 | O23: 낮음 | P23: Level, 3M/12M 변화, spread/ratio | R23: 2006-01 ~ 2026-07 | S23: 월간 | T23: 주택 거래통계는 기준월 익월 말일경 공표. | U23: 현재 수집본: 15개 시도 + 서울 25개 자치구. 광주·전남이 통째로 누락. 서울시 합계 포함. | V23: Y | W23: N | X23: 한국부동산원 | Z23: https://www.reb.or.kr/reb/cm/cntnts/cntntsView.do?cntntsId=1065&mi=9819 | AA23: 부동산원_아파트거래현황.csv | AB23: 현재 수집본 지역 누락을 먼저 수정해야 17개 시도 패널 사용 가능. 거래신고 기반이므로 취소·정정 거래 반영에 따라 과거치가 수정될 수 있음. | AF23: 보존(삭제 안 함) | AG23: 후보 유지 | AI23: 매매·전세·월세 선택에 영향을 주는 주택금융비용과 상대가격을 측정 / 보조적으로 ⑤ 시장과열·단기 트리거 성격도 존재
A24: V050 | B24: 노경수 | C24: 260919_데이터사전_노경수.xlsx | D24: 데이터목록 | E24: 27 | F24: 거시금융 | H24: 지역별 주택관련대출(예금은행) | I24: ③ 금융여건·상대가격 | J24: ⑥ 거시경기·금융시장 여건 | K24: 설명변수 후보 | L24: Housing Finance | M24: ± | N24: 0~12개월 | O24: 낮음 | P24: Level, 3M/12M 변화, spread/ratio | R24: 2006-12 ~ 2026-06 | S24: 월간 | T24: 통상 기준월 후 약 2개월 시차로 지역금융통계/ECOS에 반영(지역별 세부 일정 차이 가능). | U24: 17개 시도(서울 포함) 시도단위만. 서울 자치구 없음. 세종은 2012-09부터. | V24: N | W24: 조건부 | X24: 한국은행 | Z24: https://www.bok.or.kr/portal/main/contents.do?menuNo=200672 | AA24: ECOS_지역별_주택관련대출.csv | AB24: 예금은행 주택관련대출만 포함하여 비은행·정책금융 등을 포괄하지 않음. 지역별 공표 시차가 있어 실제 available_date 확보 권장. | AF24: 보존(삭제 안 함) | AG24: 후보 유지 | AI24: 매매·전세·월세 선택에 영향을 주는 주택금융비용과 상대가격을 측정 / 보조적으로 ⑥ 거시경기·금융시장 여건 성격도 존재
A25: V056 | B25: 박준우 | C25: 260919_데이터사전_박준우.xlsx | D25: Sheet1 | E25: 6 | H25: 은행대출금리_주택담보대출(신규취급액) | I25: ③ 금융여건·상대가격 | K25: 설명변수 후보 | L25: Financial/Relative Price | M25: ± | N25: 0~12개월 | O25: 낮음 | P25: Level, 3M/12M 변화, spread/ratio | R25: 37135 | S25: 월 | T25: 익월 말 | U25: 전국 단일값 또는 전국 표본(공통 거시변수) | V25: N(공통값) | X25: 한국은행 | Z25: https://ecos.bok.or.kr/ | AC25: 변수 성격상 전국 공통 | AF25: 보존(삭제 안 함) | AG25: 후보 유지 | AI25: 매매·전세·월세 선택에 영향을 주는 주택금융비용과 상대가격을 측정
A26: V057 | B26: 박준우 | C26: 260919_데이터사전_박준우.xlsx | D26: Sheet1 | E26: 7 | H26: 은행대출금리_전세자금(신규취급액) | I26: ③ 금융여건·상대가격 | K26: 설명변수 후보 | L26: Financial/Relative Price | M26: ± | N26: 0~12개월 | O26: 낮음 | P26: Level, 3M/12M 변화, spread/ratio | R26: 42005 | S26: 월 | T26: 익월 말 | U26: 전국 단일값 또는 전국 표본(공통 거시변수) | V26: N(공통값) | X26: 한국은행 | Z26: https://ecos.bok.or.kr/ | AC26: 변수 성격상 전국 공통 | AF26: 보존(삭제 안 함) | AG26: 후보 유지 | AI26: 매매·전세·월세 선택에 영향을 주는 주택금융비용과 상대가격을 측정
A27: V059 | B27: 박준우 | C27: 260919_데이터사전_박준우.xlsx | D27: Sheet1 | E27: 9 | H27: 비은행대출금리_주택담보대출 | I27: ③ 금융여건·상대가격 | K27: 설명변수 후보 | L27: Financial/Relative Price | M27: ± | N27: 0~12개월 | O27: 낮음 | P27: Level, 3M/12M 변화, spread/ratio | R27: 41640 | S27: 월 | T27: 익월 말 | U27: 전국 단일값 또는 전국 표본(공통 거시변수) | V27: N(공통값) | X27: 한국은행 | Y27: BEDBMC41 | Z27: https://ecos.bok.or.kr/ | AC27: 변수 성격상 전국 공통 | AF27: 보존(삭제 안 함) | AG27: 후보 유지 | AI27: 매매·전세·월세 선택에 영향을 주는 주택금융비용과 상대가격을 측정
A28: V060 | B28: 박준우 | C28: 260919_데이터사전_박준우.xlsx | D28: Sheet1 | E28: 10 | H28: 대출행태서베이(대출태도)_은행_가계(주택) | I28: ③ 금융여건·상대가격 | K28: 설명변수 후보 | L28: Financial/Relative Price | M28: ± | N28: 0~12개월 | O28: 낮음 | P28: Level, 3M/12M 변화, spread/ratio | R28: 37500 | S28: 분기 | T28: 분기 첫 월 | U28: 전국 단일값 또는 전국 표본(공통 거시변수) | V28: N(공통값) | X28: 한국은행 | Z28: https://ecos.bok.or.kr/ | AC28: 변수 성격상 전국 공통 | AF28: 보존(삭제 안 함) | AG28: 후보 유지 | AI28: 매매·전세·월세 선택에 영향을 주는 주택금융비용과 상대가격을 측정
A29: V069 | B29: 박준우 | C29: 260919_데이터사전_박준우.xlsx | D29: Sheet1 | E29: 19 | H29: 예금취급기관 가계대출(용도별) 전체대출/주택관련대출 | I29: ③ 금융여건·상대가격 | K29: 설명변수 후보 | L29: Financial/Relative Price | M29: ± | N29: 0~12개월 | O29: 낮음 | P29: Level, 3M/12M 변화, spread/ratio | S29: 월 | T29: 익익월 | U29: 전국 또는 시도단위 여부 원표 확인 필요 | X29: KOSIS/해당 작성기관 | Z29: https://kosis.kr/ | AC29: 원표 지역단위 추가 확인 필요 | AF29: 보존(삭제 안 함) | AG29: 후보 유지 | AI29: 매매·전세·월세 선택에 영향을 주는 주택금융비용과 상대가격을 측정
A30: V071 | B30: 박준우 | C30: 260919_데이터사전_박준우.xlsx | D30: Sheet1 | E30: 21 | H30: 주택금융공사 및 주택도시기금의 정책대출 | I30: ③ 금융여건·상대가격 | K30: 설명변수 후보 | L30: Financial/Relative Price | M30: ± | N30: 0~12개월 | O30: 낮음 | P30: Level, 3M/12M 변화, spread/ratio | R30: 42186 | S30: 월 | T30: 익익월 | U30: 전국 또는 시도단위 여부 원표 확인 필요 | X30: KOSIS/해당 작성기관 | Z30: https://kosis.kr/ | AC30: 원표 지역단위 추가 확인 필요 | AF30: 보존(삭제 안 함) | AG30: 후보 유지 | AI30: 매매·전세·월세 선택에 영향을 주는 주택금융비용과 상대가격을 측정
A31: V005 | B31: 권태혁 | C31: 260919_데이터사전_권태혁.xlsx | D31: 변수현황 | E31: 10 | F31: 가격 | G31: P5 | H31: 아파트 월세 수급동향 | I31: ④ 임대시장 수급·전환 구조 | K31: 설명변수 후보 | L31: Market Structure/Flow | M31: + | N31: 0~6개월 | O31: 낮음 | P31: 월세비중, 전세→월세 전환, 거래량/구성 변화, 3M 변화 | R31: 2015.07–2026.08 | S31: 월 | T31: 기준월 익월 15일 전후 | U31: 17개 시도 | V31: N | W31: Y | X31: 한국부동산원 R-ONE | Y31: A_2024_00078 | Z31: https://www.reb.or.kr/r-one/portal/stat/easyStatPage/A_2024_00078.do | AB31: 서울 25개 구 공식 통계표는 없음 / 시도만 제공 | AC31: 노경수 데이터사전의 동일/유사 통계 | AF31: 보존(삭제 안 함) | AG31: 후보 유지 | AI31: 실제 임대계약의 수급, 전세↔월세 전환 및 거래구성 변화를 측정
A32: V006 | B32: 권태혁 | C32: 260919_데이터사전_권태혁.xlsx | D32: 변수현황 | E32: 11 | F32: 가격 | G32: P6 | H32: 아파트 전월세 실거래 원본 | I32: ④ 임대시장 수급·전환 구조 | K32: 설명변수 후보 | L32: Market Structure/Flow | M32: + | N32: 0~6개월 | O32: 낮음 | P32: 월세비중, 전세→월세 전환, 거래량/구성 변화, 3M 변화 | R32: 2011.01–2026.08 | S32: 건 | T32: API 일 1회 갱신; 계약 신고는 체결 후 30일 이내 | U32: 서울 25개 구 | V32: Y | X32: 국토교통부 | Y32: RTMSDataSvcAptRent | Z32: https://www.data.go.kr/data/15126474/openapi.do | AB32: 2011~2015.05 API와 이후 CSV. 표의 숫자는 월세 원본 행수 / 계약 신고 원본. 월세행수는 보조 집계 | AC32: 국토부 실거래 API 기술문서 | AF32: 보존(삭제 안 함) | AG32: 후보 유지 | AI32: 실제 임대계약의 수급, 전세↔월세 전환 및 거래구성 변화를 측정
A33: V032 | B33: 노경수 | C33: 260919_데이터사전_노경수.xlsx | D33: 데이터목록 | E33: 9 | F33: 시장수급 | H33: 아파트 전세수급동향지수 | I33: ④ 임대시장 수급·전환 구조 | K33: 설명변수 후보 | L33: Market Structure/Flow | M33: + | N33: 0~6개월 | O33: 낮음 | P33: 월세비중, 전세→월세 전환, 거래량/구성 변화, 3M 변화 | R33: 2012-07 ~ 2026-08 | S33: 월간 | T33: 기준월 익월 15일(전국주택가격동향조사와 함께 공표) | U33: 17개 시도(서울 포함) 시도단위만. 서울 자치구 없음. 세종은 2012-12부터. | V33: N | W33: 조건부 | X33: 한국부동산원 | Z33: https://www.reb.or.kr/reb/cm/cntnts/cntntsView.do?cntntsId=1033&mi=10333&statId=S234820263 | AA33: 부동산원_수급동향_아파트.csv | AB33: 설문·표본 기반 체감 수급지수로 실제 거래량과 개념이 다름. 100 기준 해석과 조사개편 이력 확인 필요. 서울 자치구 분석에는 사용 불가. | AF33: 보존(삭제 안 함) | AG33: 후보 유지 | AI33: 실제 임대계약의 수급, 전세↔월세 전환 및 거래구성 변화를 측정
A34: V033 | B34: 노경수 | C34: 260919_데이터사전_노경수.xlsx | D34: 데이터목록 | E34: 10 | F34: 시장수급 | H34: 아파트 월세수급동향지수 | I34: ④ 임대시장 수급·전환 구조 | K34: 설명변수 후보 | L34: Market Structure/Flow | M34: + | N34: 0~6개월 | O34: 낮음 | P34: 월세비중, 전세→월세 전환, 거래량/구성 변화, 3M 변화 | R34: 2015-07 ~ 2026-08 | S34: 월간 | T34: 기준월 익월 15일(전국주택가격동향조사와 함께 공표) | U34: 17개 시도(서울 포함) 시도단위만. 서울 자치구 없음. | V34: N | W34: 조건부 | X34: 한국부동산원 | Z34: https://www.reb.or.kr/reb/cm/cntnts/cntntsView.do?cntntsId=1033&mi=10333&statId=S234820263 | AA34: 부동산원_수급동향_아파트.csv | AB34: 설문·표본 기반 체감 수급지수로 실제 거래량과 개념이 다름. 100 기준 해석과 조사개편 이력 확인 필요. 서울 자치구 분석에는 사용 불가. | AF34: 보존(삭제 안 함) | AG34: 후보 유지 | AI34: 실제 임대계약의 수급, 전세↔월세 전환 및 거래구성 변화를 측정
A35: V034 | B35: 노경수 | C35: 260919_데이터사전_노경수.xlsx | D35: 데이터목록 | E35: 11 | F35: 시장수급 | H35: 구(舊) 수급동향 통합지수 | I35: ④ 임대시장 수급·전환 구조 | K35: 설명변수 후보 | L35: Market Structure/Flow | M35: + | N35: 0~6개월 | O35: 낮음 | P35: 월세비중, 전세→월세 전환, 거래량/구성 변화, 3M 변화 | R35: 2010-06 ~ 2015-06 | S35: 월간(중지통계) | T35: 현재 신규 공표 없음. 2015년 7월 월세가격동향조사가 전국주택가격동향조사에 통합되며 중지. | U35: 8개 지역만: 서울·인천·경기·부산·대구·광주·대전·울산. 서울 자치구 없음. | V35: N | W35: N | X35: 한국부동산원 | Z35: https://www.reb.or.kr/reb/cm/cntnts/cntntsView.do?cntntsId=1300&mi=9989 | AA35: 부동산원_수급동향구_통합.csv | AB35: 현행 수급동향과 별개 조사이며 2012~2015 기간이 겹침. 단순 이어붙이기 금지. 연구상 필요 시 구조변화 더미 또는 별도 과거 설명변수로 사용. | AF35: 보존(삭제 안 함) | AG35: 후보 유지 | AI35: 실제 임대계약의 수급, 전세↔월세 전환 및 거래구성 변화를 측정
A36: V035 | B36: 노경수 | C36: 260919_데이터사전_노경수.xlsx | D36: 데이터목록 | E36: 12 | F36: 거래 | H36: 행정구역별 아파트 거래현황(동·호수, 면적) | I36: ④ 임대시장 수급·전환 구조 | J36: ⑤ 시장과열·단기 트리거 | K36: 설명변수 후보 | L36: Market Structure/Flow | M36: + | N36: 0~6개월 | O36: 낮음 | P36: 월세비중, 전세→월세 전환, 거래량/구성 변화, 3M 변화 | R36: 2006-01 ~ 2026-07 | S36: 월간 | T36: 주택 거래통계는 기준월 익월 말일경 공표. | U36: 현재 수집본: 15개 시도 + 서울 25개 자치구. 광주·전남이 통째로 누락. 서울시 합계 포함. | V36: Y | W36: N | X36: 한국부동산원 | Z36: https://www.reb.or.kr/reb/cm/cntnts/cntntsView.do?cntntsId=1065&mi=9819 | AA36: 부동산원_아파트거래현황.csv | AB36: 원 통계는 전국 시군구 공표 대상인데 현재 전처리본에서 광주·전남 누락. raw의 원 지역명(CLS_FULLNM 등)을 보존하고 지역 파싱 로직 재점검 필요. 세종 2012-07, 제주 2006-07부터. | AF36: 보존(삭제 안 함) | AG36: 후보 유지 | AI36: 실제 임대계약의 수급, 전세↔월세 전환 및 거래구성 변화를 측정 / 보조적으로 ⑤ 시장과열·단기 트리거 성격도 존재
A37: V001 | B37: 권태혁 | C37: 260919_데이터사전_권태혁.xlsx | D37: 변수현황 | E37: 6 | F37: 가격 | G37: P1 | H37: 아파트 월세통합가격지수 | I37: ⑤ 시장과열·단기 트리거 | K37: 종속변수 후보 / 시차 사용 시 설명변수 | L37: Market Signal | M37: + | N37: 0~3개월(시차 사용 시) | O37: 높음 | P37: 1M/3M/6M 변동률, z-score, 급등더미 | R37: 2015.06–2026.08 | S37: 월 | T37: 기준월 익월 15일 전후 | U37: 17개 시도·서울 25개 구 | V37: Y | W37: Y | X37: 한국부동산원 R-ONE | Y37: A_2024_00054 | Z37: https://www.reb.or.kr/r-one/portal/stat/easyStatPage/A_2024_00054.do | AB37: Y1~Y4 목표변수. 2011~2015.05 공식 지수는 없음 / 2015.06 시작. Y1~Y4 목표변수 | AC37: 노경수 데이터사전의 동일/유사 통계 | AE37: 유사/중복군_월세통합가격지수 | AF37: 보존(삭제 안 함) | AG37: 후보 유지 | AH37: 동일월 예측변수로 사용 금지; 종속변수 정의 또는 lagged momentum 용도 | AI37: 가격·심리·거래의 단기 모멘텀 또는 급변동 직전 신호를 측정
A38: V037 | B38: 노경수 | C38: 260919_데이터사전_노경수.xlsx | D38: 데이터목록 | E38: 14 | F38: 심리 | H38: 주택시장 소비심리지수 | I38: ⑤ 시장과열·단기 트리거 | J38: ⑥ 거시경기·금융시장 여건 | K38: 설명변수 후보 | L38: Market Signal | M38: + | N38: 0~6개월 | O38: 중간 | P38: Level, 3M 변화, z-score | R38: 2011-07 ~ 2026-07 | S38: 월간 | T38: 익월 중순. 최근 예: 2026-07분 8/18, 2026-08분 9/16 공표. | U38: 17개 시도(서울 포함) 시도단위만. 서울 자치구 없음. 세종·제주는 2018-12부터. | V38: N | W38: 조건부 | X38: 국토연구원 | Z38: https://www.krihs.re.kr/board.es?act=view&bid=0054&list_no=398639&mid=a10109000000&tag= | AA38: 부동산원_주택시장소비심리지수.csv | AB38: 설문 기반 심리지수로 가격·거래 실측치와 다름. 세종·제주 후발 편입 때문에 2018-12 이전 17개 시도 완전패널이 아님. | AF38: 보존(삭제 안 함) | AG38: 후보 유지 | AI38: 가격·심리·거래의 단기 모멘텀 또는 급변동 직전 신호를 측정 / 보조적으로 ⑥ 거시경기·금융시장 여건 성격도 존재
A39: V061 | B39: 박준우 | C39: 260919_데이터사전_박준우.xlsx | D39: Sheet1 | E39: 11 | H39: 소비자동향조사_주택가격전망CSI_서울 | I39: ⑤ 시장과열·단기 트리거 | J39: ⑥ 거시경기·금융시장 여건 | K39: 설명변수 후보 | L39: Market Signal | M39: + | N39: 0~6개월 | O39: 중간 | P39: Level, 3M 변화, z-score | R39: 41275 | S39: 월 | T39: 월말 | U39: 서울 권역 | V39: N(서울 공통) | X39: 한국은행 | Z39: https://ecos.bok.or.kr/ | AC39: 지표명 기준 | AF39: 보존(삭제 안 함) | AG39: 후보 유지 | AI39: 가격·심리·거래의 단기 모멘텀 또는 급변동 직전 신호를 측정 / 보조적으로 ⑥ 거시경기·금융시장 여건 성격도 존재
A40: V062 | B40: 박준우 | C40: 260919_데이터사전_박준우.xlsx | D40: Sheet1 | E40: 12 | H40: 소비자동향조사_주택가격전망CSI_6대광역시 | I40: ⑤ 시장과열·단기 트리거 | J40: ⑥ 거시경기·금융시장 여건 | K40: 설명변수 후보 | L40: Market Signal | M40: + | N40: 0~6개월 | O40: 중간 | P40: Level, 3M 변화, z-score | R40: 41275 | S40: 월 | T40: 월말 | U40: 6대 광역시 권역 | V40: N | X40: 한국은행 | Z40: https://ecos.bok.or.kr/ | AC40: 지표명 기준 | AF40: 보존(삭제 안 함) | AG40: 후보 유지 | AI40: 가격·심리·거래의 단기 모멘텀 또는 급변동 직전 신호를 측정 / 보조적으로 ⑥ 거시경기·금융시장 여건 성격도 존재
...

Sheet Driver_Map
A1: 동인 | B1: 전체 변수 수 | C1: 권태혁 | D1: 노경수 | E1: 박준우 | F1: 고 Leakage | G1: 설명
A2: ① 임차수요 압력 | B2: =COUNTIF(Variable_Master!$I:$I,A2) -> 7 | C2: =COUNTIFS(Variable_Master!$I:$I,A2,Variable_Master!$B:$B,C$1) -> 7 | D2: =COUNTIFS(Variable_Master!$I:$I,A2,Variable_Master!$B:$B,D$1) -> 0 | E2: =COUNTIFS(Variable_Master!$I:$I,A2,Variable_Master!$B:$B,E$1) -> 0 | F2: =COUNTIFS(Variable_Master!$I:$I,A2,Variable_Master!$O:$O,"높음") -> 0 | G2: 지역별 인구·가구·이동·고용·소득 등 임차수요의 기초 펀더멘털을 측정
A3: ② 주택공급·재고 여건 | B3: =COUNTIF(Variable_Master!$I:$I,A3) -> 8 | C3: =COUNTIFS(Variable_Master!$I:$I,A3,Variable_Master!$B:$B,C$1) -> 4 | D3: =COUNTIFS(Variable_Master!$I:$I,A3,Variable_Master!$B:$B,D$1) -> 1 | E3: =COUNTIFS(Variable_Master!$I:$I,A3,Variable_Master!$B:$B,E$1) -> 3 | F3: =COUNTIFS(Variable_Master!$I:$I,A3,Variable_Master!$O:$O,"높음") -> 0 | G3: 주택의 물리적 재고와 신규 공급·미분양 등 공급 흡수력을 측정
A4: ③ 금융여건·상대가격 | B4: =COUNTIF(Variable_Master!$I:$I,A4) -> 14 | C4: =COUNTIFS(Variable_Master!$I:$I,A4,Variable_Master!$B:$B,C$1) -> 4 | D4: =COUNTIFS(Variable_Master!$I:$I,A4,Variable_Master!$B:$B,D$1) -> 4 | E4: =COUNTIFS(Variable_Master!$I:$I,A4,Variable_Master!$B:$B,E$1) -> 6 | F4: =COUNTIFS(Variable_Master!$I:$I,A4,Variable_Master!$O:$O,"높음") -> 0 | G4: 매매·전세·월세 선택에 영향을 주는 주택금융비용과 상대가격을 측정
A5: ④ 임대시장 수급·전환 구조 | B5: =COUNTIF(Variable_Master!$I:$I,A5) -> 6 | C5: =COUNTIFS(Variable_Master!$I:$I,A5,Variable_Master!$B:$B,C$1) -> 2 | D5: =COUNTIFS(Variable_Master!$I:$I,A5,Variable_Master!$B:$B,D$1) -> 4 | E5: =COUNTIFS(Variable_Master!$I:$I,A5,Variable_Master!$B:$B,E$1) -> 0 | F5: =COUNTIFS(Variable_Master!$I:$I,A5,Variable_Master!$O:$O,"높음") -> 0 | G5: 실제 임대계약의 수급, 전세↔월세 전환 및 거래구성 변화를 측정
A6: ⑤ 시장과열·단기 트리거 | B6: =COUNTIF(Variable_Master!$I:$I,A6) -> 5 | C6: =COUNTIFS(Variable_Master!$I:$I,A6,Variable_Master!$B:$B,C$1) -> 1 | D6: =COUNTIFS(Variable_Master!$I:$I,A6,Variable_Master!$B:$B,D$1) -> 1 | E6: =COUNTIFS(Variable_Master!$I:$I,A6,Variable_Master!$B:$B,E$1) -> 3 | F6: =COUNTIFS(Variable_Master!$I:$I,A6,Variable_Master!$O:$O,"높음") -> 1 | G6: 가격·심리·거래의 단기 모멘텀 또는 급변동 직전 신호를 측정
A7: ⑥ 거시경기·금융시장 여건 | B7: =COUNTIF(Variable_Master!$I:$I,A7) -> 12 | C7: =COUNTIFS(Variable_Master!$I:$I,A7,Variable_Master!$B:$B,C$1) -> 0 | D7: =COUNTIFS(Variable_Master!$I:$I,A7,Variable_Master!$B:$B,D$1) -> 7 | E7: =COUNTIFS(Variable_Master!$I:$I,A7,Variable_Master!$B:$B,E$1) -> 5 | F7: =COUNTIFS(Variable_Master!$I:$I,A7,Variable_Master!$O:$O,"높음") -> 0 | G7: 전 자치구에 공통으로 작용하는 경기·금리·유동성·금융시장 국면을 측정
A8: 합계 | B8: =SUM(B2:B7) -> 52 | C8: =SUM(C2:C7) -> 18 | D8: =SUM(D2:D7) -> 17 | E8: =SUM(E2:E7) -> 17 | F8: =SUM(F2:F7) -> 1 | G8: 모든 원본 변수/자료행을 보존

Sheet Source_Inventory
A1: 수집자 | B1: 원본파일 | C1: 변수명 | D1: 출처기관 | E1: 표ID/CODE | F1: URL | G1: 빈도 | H1: 발표·가용 시점 | I1: 지역 범위 | J1: 수록기간
A2: 권태혁 | B2: 260919_데이터사전_권태혁.xlsx | C2: 아파트 월세통합가격지수 | D2: 한국부동산원 R-ONE | E2: A_2024_00054 | F2: https://www.reb.or.kr/r-one/portal/stat/easyStatPage/A_2024_00054.do | G2: 월 | H2: 기준월 익월 15일 전후 | I2: 17개 시도·서울 25개 구 | J2: 2015.06–2026.08
A3: 권태혁 | B3: 260919_데이터사전_권태혁.xlsx | C3: 아파트 매매가격지수 | D3: 한국부동산원 R-ONE | E3: A_2024_00045 | F3: https://www.reb.or.kr/r-one/portal/stat/easyStatPage/A_2024_00045.do | G3: 월 | H3: 기준월 익월 15일 전후 | I3: 17개 시도·서울 25개 구 | J3: 2011.01–2026.08
A4: 권태혁 | B4: 260919_데이터사전_권태혁.xlsx | C4: 아파트 전세가율 | D4: 한국부동산원 R-ONE | E4: A_2024_00072 | F4: https://www.reb.or.kr/r-one/portal/stat/easyStatPage/A_2024_00072.do | G4: 월 | H4: 월간 공표; 실제 공표일 별도 관리 권장 | I4: 17개 시도·서울 25개 구 | J4: 2012.01–2026.08
A5: 권태혁 | B5: 260919_데이터사전_권태혁.xlsx | C5: 아파트 전월세전환율 | D5: 한국부동산원 R-ONE | E5: A_2024_00156 | F5: https://www.reb.or.kr/r-one/portal/stat/easyStatPage/A_2024_00156.do | G5: 월 | H5: 통상 익익월 15일(가격지수보다 1개월 추가 시차) | I5: 17개 시도·서울 25개 구 | J5: 2011.01–2026.07
A6: 권태혁 | B6: 260919_데이터사전_권태혁.xlsx | C6: 아파트 월세 수급동향 | D6: 한국부동산원 R-ONE | E6: A_2024_00078 | F6: https://www.reb.or.kr/r-one/portal/stat/easyStatPage/A_2024_00078.do | G6: 월 | H6: 기준월 익월 15일 전후 | I6: 17개 시도 | J6: 2015.07–2026.08
A7: 권태혁 | B7: 260919_데이터사전_권태혁.xlsx | C7: 아파트 전월세 실거래 원본 | D7: 국토교통부 | E7: RTMSDataSvcAptRent | F7: https://www.data.go.kr/data/15126474/openapi.do | G7: 건 | H7: API 일 1회 갱신; 계약 신고는 체결 후 30일 이내 | I7: 서울 25개 구 | J7: 2011.01–2026.08
A8: 권태혁 | B8: 260919_데이터사전_권태혁.xlsx | C8: 아파트 매매 실거래 원본 | D8: 국토교통부 | E8: RTMSDataSvcAptTrade | F8: https://www.data.go.kr/data/15126469/openapi.do | G8: 건 | H8: API/신고자료 수시 갱신; 월 집계 시 신고·정정 시차 고려 | I8: 서울 25개 구 | J8: 2011.01–2026.08
A9: 권태혁 | B9: 260919_데이터사전_권태혁.xlsx | C9: 월세 ÷ 매매가격 비율 | F9: https://www.data.go.kr/data/15126474/openapi.do ; https://www.data.go.kr/data/15126469/openapi.do | G9: 월(설계) | H9: 파생변수: 구성 원자료 중 가장 늦은 available_date 적용 | I9: 서울 우선 | J9: 미산출
A10: 권태혁 | B10: 260919_데이터사전_권태혁.xlsx | C10: 주민등록 인구 | D10: 행정안전부 | E10: 주민등록인구통계 | F10: https://jumin.mois.go.kr/statMonth.do | G10: 월 | H10: 기준월 익월 1일 전후 | I10: 17개 시도·서울 25개 구 | J10: 2011.01–2026.08
A11: 권태혁 | B11: 260919_데이터사전_권태혁.xlsx | C11: 주민등록 세대수 | D11: 행정안전부 | E11: 주민등록인구통계 | F11: https://jumin.mois.go.kr/statMonth.do | G11: 월 | H11: 기준월 익월 1일 전후 | I11: 17개 시도·서울 25개 구 | J11: 2011.01–2026.08
A12: 권태혁 | B12: 260919_데이터사전_권태혁.xlsx | C12: 20–29세·30–39세 인구 | D12: 행정안전부 | E12: 연령별인구현황 | F12: https://jumin.mois.go.kr/ageStatMonth.do | G12: 월 | H12: 기준월 익월 1일 전후 | I12: 17개 시도·서울 25개 구 | J12: 2011.01–2026.08
A13: 권태혁 | B13: 260919_데이터사전_권태혁.xlsx | C13: 순이동자수 | D13: KOSIS 국내인구이동통계 | E13: 101/DT_1B26001_A01 | F13: https://kosis.kr/statHtml/statHtml.do?orgId=101&tblId=DT_1B26001_A01&conn_path=I2 | G13: 월 | H13: 통상 익월 말 전후 | I13: 17개 시도·서울 25개 구 | J13: 2011.01–2026.07
A14: 권태혁 | B14: 260919_데이터사전_권태혁.xlsx | C14: 고용률·취업자 | D14: KOSIS 경제활동인구조사·지역별고용조사 | E14: DT_1DA7004S / DT_1ES3A01S | F14: https://kosis.kr/statHtml/statHtml.do?orgId=101&tblId=DT_1DA7004S&conn_path=I2 | G14: 월/반기 | H14: 시도 월별: 익월 중순 / 서울 구 반기: 4월조사→8월, 10월조사→익년 2월 | I14: 시도 월별·서울 구 반기 | J14: 시도 2011.01~ / 구 2021H1~
A15: 권태혁 | B15: 260919_데이터사전_권태혁.xlsx | C15: 주소지 기준 근로소득 | D15: KOSIS 국세통계 | E15: 133/DT_133001N_4215 | F15: https://kosis.kr/statHtml/statHtml.do?orgId=133&tblId=DT_133001N_4215&conn_path=I2 | G15: 년 | H15: 연간 공표; 공표시차가 길어 available_date 별도 관리 | I15: 17개 시도·서울 25개 구 | J15: 2016–2023 연간
A16: 권태혁 | B16: 260919_데이터사전_권태혁.xlsx | C16: 1인당 GRDP | D16: KOSIS 지역소득 | E16: 101/DT_1C96 | F16: https://kosis.kr/statHtml/statHtml.do?orgId=101&tblId=DT_1C96&conn_path=I2 | G16: 년 | H16: 연간 공표; 공표시차가 길어 available_date 별도 관리 | I16: 17개 시도 | J16: 2011–2024 연간
A17: 권태혁 | B17: 260919_데이터사전_권태혁.xlsx | C17: 서울 구별 지역내총부가가치 | D17: KOSIS 서울통계 | E17: 201/DT_201012_D040031 | F17: https://kosis.kr/statHtml/statHtml.do?orgId=201&tblId=DT_201012_D040031&conn_path=I2 | G17: 년 | H17: 연간 공표; 공표시차가 길어 available_date 별도 관리 | I17: 서울 25개 구 | J17: 2011–2023 연간
A18: 권태혁 | B18: 260919_데이터사전_권태혁.xlsx | C18: 1인당 가계총처분가능소득 | D18: KOSIS 지역소득 | E18: 101/DT_1C96 | F18: https://kosis.kr/statHtml/statHtml.do?orgId=101&tblId=DT_1C96&conn_path=I2 | G18: 년 | H18: 연간 공표; 공표시차가 길어 available_date 별도 관리 | I18: 17개 시도 | J18: 2011–2024 연간
A19: 권태혁 | B19: 260919_데이터사전_권태혁.xlsx | C19: 전체 주택 인허가 호수 | D19: 국토교통부 통계누리 | E19: 통계표 XLSX | F19: https://stat.molit.go.kr/portal/cate/statMetaView.do?hRsId=31 | G19: 월 | H19: 기준월 익월 말 전후 | I19: 17개 시도 | J19: 2011.01–2025.12
A20: 권태혁 | B20: 260919_데이터사전_권태혁.xlsx | C20: 전체 주택 착공 호수 | F20: https://stat.molit.go.kr/portal/cate/statMetaView.do?hRsId=31 | G20: 월 | H20: 기준월 익월 말 전후 | I20: 17개 시도 | J20: 2011.01–2025.12
A21: 권태혁 | B21: 260919_데이터사전_권태혁.xlsx | C21: 전체 주택 준공 호수 | D21: 국토교통부 통계누리 | E21: 통계표 XLSX | F21: https://stat.molit.go.kr/portal/cate/statMetaView.do?hRsId=31 | G21: 월 | H21: 기준월 익월 말 전후 | I21: 17개 시도 | J21: 2011.01–2025.12
A22: 권태혁 | B22: 260919_데이터사전_권태혁.xlsx | C22: 아파트 인허가 호수 | D22: KOSIS 주택건설실적통계 | E22: 116/DT_MLTM_1948 | F22: https://kosis.kr/statHtml/statHtml.do?orgId=116&tblId=DT_MLTM_1948&conn_path=I2 | G22: 월 | H22: 기준월 익월 말 전후 | I22: 17개 시도 | J22: 2011.01–2026.07
A23: 권태혁 | B23: 260919_데이터사전_권태혁.xlsx | C23: 아파트 착공 호수 | D23: KOSIS 주택건설실적통계 | E23: 116/DT_MLTM_5387 | F23: https://kosis.kr/statHtml/statHtml.do?orgId=116&tblId=DT_MLTM_5387&conn_path=I2 | G23: 월 | H23: 기준월 익월 말 전후 | I23: 17개 시도 | J23: 2011.01–2026.07
A24: 권태혁 | B24: 260919_데이터사전_권태혁.xlsx | C24: 아파트 준공 호수 | D24: KOSIS 주택건설실적통계 | E24: 116/DT_MLTM_5373 | F24: https://kosis.kr/statHtml/statHtml.do?orgId=116&tblId=DT_MLTM_5373&conn_path=I2 | G24: 월 | H24: 기준월 익월 말 전후 | I24: 17개 시도 | J24: 2011.01–2026.07
A25: 권태혁 | B25: 260919_데이터사전_권태혁.xlsx | C25: 서울 구 주거용 신축허가 | D25: KOSIS 서울통계 | E25: 201/DT_201004_O090005 | F25: https://stat.eseoul.go.kr/statHtml/statHtml.do?orgId=201&tblId=DT_201004_O090005&conn_path=I2 | G25: 년 | H25: 연간 공표; 실제 공표일 별도 확인 | I25: 서울 25개 구 | J25: 2011–2024 연간
A26: 노경수 | B26: 260919_데이터사전_노경수.xlsx | C26: 아파트 매매가격지수 | D26: 한국부동산원 | F26: https://www.reb.or.kr/reb/cm/cntnts/cntntsView.do?cntntsId=1033&mi=10333&statId=S234820263 | G26: 월간 | H26: 기준월 익월 15일(휴일이면 다음날) | I26: 17개 시도 + 서울 25개 자치구(서울시 합계 포함). 세종은 2012-11부터. | J26: 2003-11 ~ 2026-08
A27: 노경수 | B27: 260919_데이터사전_노경수.xlsx | C27: 아파트 전세가격지수 | D27: 한국부동산원 | F27: https://www.reb.or.kr/reb/cm/cntnts/cntntsView.do?cntntsId=1033&mi=10333&statId=S234820263 | G27: 월간 | H27: 기준월 익월 15일(휴일이면 다음날) | I27: 17개 시도 + 서울 25개 자치구(서울시 합계 포함). 세종은 후발 편입. | J27: 2003-11 ~ 2026-08
A28: 노경수 | B28: 260919_데이터사전_노경수.xlsx | C28: 아파트 월세가격지수 | D28: 한국부동산원 | F28: https://www.reb.or.kr/reb/cm/cntnts/cntntsView.do?cntntsId=1033&mi=10333&statId=S234820263 https://www.reb.or.kr/reb/cm/cntnts/cntntsView.do?cntntsId=1300&mi=9989 | G28: 월간 | H28: 기준월 익월 15일(휴일이면 다음날) | I28: 현재 전체로는 17개 시도 + 서울 25개 자치구. 다만 지역별 시작시점 상이(수도권 2010-06, 일부 광역시 2012-05, 다수 지역 2016-01). | J28: 2010-06 ~ 2026-08
A29: 노경수 | B29: 260919_데이터사전_노경수.xlsx | C29: 아파트 월세통합가격지수 | D29: 한국부동산원 | F29: https://www.reb.or.kr/reb/cm/cntnts/cntntsView.do?cntntsId=1033&mi=10333&statId=S234820263 | G29: 월간 | H29: 기준월 익월 15일(휴일이면 다음날) | I29: 17개 시도 + 서울 25개 자치구(서울시 합계 포함). | J29: 2015-06 ~ 2026-08
A30: 노경수 | B30: 260919_데이터사전_노경수.xlsx | C30: 아파트 전월세통합지수 | D30: 한국부동산원 | F30: https://www.reb.or.kr/reb/cm/cntnts/cntntsView.do?cntntsId=1033&mi=10333&statId=S234820263 | G30: 월간 | H30: 기준월 익월 15일(휴일이면 다음날) | I30: 17개 시도(서울 포함) 시도단위만. 서울 자치구 없음. | J30: 2015-06 ~ 2026-08
A31: 노경수 | B31: 260919_데이터사전_노경수.xlsx | C31: 아파트 지역별 전월세전환율 | D31: 한국부동산원 | F31: https://www.stgdata.co.kr/data/15047778/fileData.do?recommendDataYn=Y https://www.reb.or.kr/reb/cm/cntnts/cntntsView.do?cntntsId=1033&mi=10333&statId=S234820263 | G31: 월간 | H31: 익익월 15일. 예: 5월 월간동향 발표 시 전환율은 4월까지 공표. | I31: 17개 시도 + 서울 25개 자치구(서울시 합계 포함). 세종은 2012-07부터. | J31: 2011-01 ~ 2026-07
A32: 노경수 | B32: 260919_데이터사전_노경수.xlsx | C32: 아파트 매매수급동향지수 | D32: 한국부동산원 | F32: https://www.reb.or.kr/reb/cm/cntnts/cntntsView.do?cntntsId=1033&mi=10333&statId=S234820263 | G32: 월간 | H32: 기준월 익월 15일(전국주택가격동향조사와 함께 공표) | I32: 17개 시도(서울 포함) 시도단위만. 서울 자치구 없음. 세종은 2012-12부터. | J32: 2012-07 ~ 2026-08
A33: 노경수 | B33: 260919_데이터사전_노경수.xlsx | C33: 아파트 전세수급동향지수 | D33: 한국부동산원 | F33: https://www.reb.or.kr/reb/cm/cntnts/cntntsView.do?cntntsId=1033&mi=10333&statId=S234820263 | G33: 월간 | H33: 기준월 익월 15일(전국주택가격동향조사와 함께 공표) | I33: 17개 시도(서울 포함) 시도단위만. 서울 자치구 없음. 세종은 2012-12부터. | J33: 2012-07 ~ 2026-08
A34: 노경수 | B34: 260919_데이터사전_노경수.xlsx | C34: 아파트 월세수급동향지수 | D34: 한국부동산원 | F34: https://www.reb.or.kr/reb/cm/cntnts/cntntsView.do?cntntsId=1033&mi=10333&statId=S234820263 | G34: 월간 | H34: 기준월 익월 15일(전국주택가격동향조사와 함께 공표) | I34: 17개 시도(서울 포함) 시도단위만. 서울 자치구 없음. | J34: 2015-07 ~ 2026-08
A35: 노경수 | B35: 260919_데이터사전_노경수.xlsx | C35: 구(舊) 수급동향 통합지수 | D35: 한국부동산원 | F35: https://www.reb.or.kr/reb/cm/cntnts/cntntsView.do?cntntsId=1300&mi=9989 | G35: 월간(중지통계) | H35: 현재 신규 공표 없음. 2015년 7월 월세가격동향조사가 전국주택가격동향조사에 통합되며 중지. | I35: 8개 지역만: 서울·인천·경기·부산·대구·광주·대전·울산. 서울 자치구 없음. | J35: 2010-06 ~ 2015-06
A36: 노경수 | B36: 260919_데이터사전_노경수.xlsx | C36: 행정구역별 아파트 거래현황(동·호수, 면적) | D36: 한국부동산원 | F36: https://www.reb.or.kr/reb/cm/cntnts/cntntsView.do?cntntsId=1065&mi=9819 | G36: 월간 | H36: 주택 거래통계는 기준월 익월 말일경 공표. | I36: 현재 수집본: 15개 시도 + 서울 25개 자치구. 광주·전남이 통째로 누락. 서울시 합계 포함. | J36: 2006-01 ~ 2026-07
A37: 노경수 | B37: 260919_데이터사전_노경수.xlsx | C37: 행정구역별 아파트 매매거래현황(동·호수, 면적) | D37: 한국부동산원 | F37: https://www.reb.or.kr/reb/cm/cntnts/cntntsView.do?cntntsId=1065&mi=9819 | G37: 월간 | H37: 주택 거래통계는 기준월 익월 말일경 공표. | I37: 현재 수집본: 15개 시도 + 서울 25개 자치구. 광주·전남이 통째로 누락. 서울시 합계 포함. | J37: 2006-01 ~ 2026-07
... A39: 노경수 | B39: 260919_데이터사전_노경수.xlsx | C39: 미분양주택현황 | D39: 국토교통부/공공데이터포털 | F39: https://www.molit.go.kr/USR/NEWS/m_71/dtl.jsp?id=95092360 | G39: 월간 | H39: 국토교통부 월간 주택통계로 기준월 익월 말(최근 2026-07분 8/31 06:00) 공표. | I39: 17개 시도 + 서울 25개 자치구(서울시 합계 포함). 세종은 2012-07부터. | J39: 2007-01 ~ 2026-07
A40: 노경수 | B40: 260919_데이터사전_노경수.xlsx | C40: 주민등록 세대수 | F40: https://jumin.mois.go.kr/statGrapA.do | G40: 월간 | H40: 매월 말일 기준, 익월 1일 12시 이후 공표(휴일이면 다음 평일). | I40: 서울 25개 자치구 + 비서울 16개 시도. 현재 파일에는 서울시 전체 합계 행이 없음. | J40: 2011-01 ~ 2026-08
A41: 노경수 | B41: 260919_데이터사전_노경수.xlsx | C41: 아파트 주택건설 인허가 실적 | D41: 국토교통부/공공데이터포털 | F41: https://www.molit.go.kr/USR/NEWS/m_71/dtl.jsp?id=95092360 | G41: 월간 | H41: 국토교통부 월간 주택통계로 기준월 익월 말(최근 2026-07분 8/31 06:00) 공표. | I41: 17개 시도(서울 포함) 시도단위만. 서울 자치구 없음. 세종은 2012년부터. | J41: 2007-01 ~ 2026-07
...

Sheet Selection_Log
A1: Master ID | B1: 변수명 | C1: 1차 동인 | D1: 중복/유사 표시 | E1: Leakage Risk | F1: 현재 상태 | G1: 향후 검토 항목 | H1: 최종 판단 | I1: 판단 사유
A2: V001 | B2: 아파트 월세통합가격지수 | C2: ⑤ 시장과열·단기 트리거 | D2: 유사/중복군_월세통합가격지수 | E2: 높음 | F2: 보존 | G2: 중복성, 시점/누출 | H2: 미정
A3: V002 | B3: 아파트 매매가격지수 | C3: ③ 금융여건·상대가격 | D3: 유사/중복군_매매가격지수 | E3: 낮음 | F3: 보존 | G3: 중복성 | H3: 미정
A4: V003 | B4: 아파트 전세가율 | C4: ③ 금융여건·상대가격 | E4: 낮음 | F4: 보존 | G4: 기본 검토 | H4: 미정
A5: V004 | B5: 아파트 전월세전환율 | C5: ③ 금융여건·상대가격 | D5: 유사/중복군_전월세전환율 | E5: 낮음 | F5: 보존 | G5: 중복성 | H5: 미정
A6: V005 | B6: 아파트 월세 수급동향 | C6: ④ 임대시장 수급·전환 구조 | E6: 낮음 | F6: 보존 | G6: 자치구 미지원 | H6: 미정
A7: V006 | B7: 아파트 전월세 실거래 원본 | C7: ④ 임대시장 수급·전환 구조 | E7: 낮음 | F7: 보존 | G7: 기본 검토 | H7: 미정
A8: V007 | B8: 아파트 매매 실거래 원본 | C8: ③ 금융여건·상대가격 | E8: 낮음 | F8: 보존 | G8: 기본 검토 | H8: 미정
A9: V008 | B9: 월세 ÷ 매매가격 비율 | C9: ③ 금융여건·상대가격 | E9: 낮음 | F9: 보존 | G9: 자치구 미지원 | H9: 미정
A10: V009 | B10: 주민등록 인구 | C10: ① 임차수요 압력 | E10: 낮음 | F10: 보존 | G10: 기본 검토 | H10: 미정
A11: V010 | B11: 주민등록 세대수 | C11: ① 임차수요 압력 | D11: 유사/중복군_주민등록세대수 | E11: 낮음 | F11: 보존 | G11: 중복성 | H11: 미정
A12: V011 | B12: 20–29세·30–39세 인구 | C12: ① 임차수요 압력 | E12: 낮음 | F12: 보존 | G12: 기본 검토 | H12: 미정
A13: V012 | B13: 순이동자수 | C13: ① 임차수요 압력 | E13: 낮음 | F13: 보존 | G13: 기본 검토 | H13: 미정
A14: V013 | B14: 고용률·취업자 | C14: ① 임차수요 압력 | E14: 낮음 | F14: 보존 | G14: 자치구 미지원 | H14: 미정
A15: V014 | B15: 주소지 기준 근로소득 | C15: ① 임차수요 압력 | E15: 낮음 | F15: 보존 | G15: 기본 검토 | H15: 미정
A16: V015 | B16: 1인당 GRDP | C16: ① 임차수요 압력 | E16: 낮음 | F16: 보존 | G16: 자치구 미지원 | H16: 미정
A17: V016 | B17: 서울 구별 지역내총부가가치 | C17: ① 임차수요 압력 | E17: 낮음 | F17: 보존 | G17: 기본 검토 | H17: 미정
A18: V017 | B18: 1인당 가계총처분가능소득 | C18: ① 임차수요 압력 | E18: 낮음 | F18: 보존 | G18: 자치구 미지원 | H18: 미정
A19: V018 | B19: 전체 주택 인허가 호수 | C19: ② 주택공급·재고 여건 | E19: 낮음 | F19: 보존 | G19: 자치구 미지원 | H19: 미정
A20: V019 | B20: 전체 주택 착공 호수 | C20: ② 주택공급·재고 여건 | E20: 낮음 | F20: 보존 | G20: 자치구 미지원 | H20: 미정
A21: V020 | B21: 전체 주택 준공 호수 | C21: ② 주택공급·재고 여건 | E21: 낮음 | F21: 보존 | G21: 자치구 미지원 | H21: 미정
A22: V021 | B22: 아파트 인허가 호수 | C22: ② 주택공급·재고 여건 | E22: 낮음 | F22: 보존 | G22: 자치구 미지원 | H22: 미정
A23: V022 | B23: 아파트 착공 호수 | C23: ② 주택공급·재고 여건 | E23: 낮음 | F23: 보존 | G23: 자치구 미지원 | H23: 미정
... A25: V024 | B25: 서울 구 주거용 신축허가 | C25: ② 주택공급·재고 여건 | E25: 낮음 | F25: 보존 | G25: 기본 검토 | H25: 미정
A26: V025 | B26: 아파트 매매가격지수 | C26: ③ 금융여건·상대가격 | D26: 유사/중복군_매매가격지수 | E26: 낮음 | F26: 보존 | G26: 중복성 | H26: 미정
A27: V026 | B27: 아파트 전세가격지수 | C27: ③ 금융여건·상대가격 | E27: 낮음 | F27: 보존 | G27: 기본 검토 | H27: 미정
A28: V027 | B28: 아파트 월세가격지수 | C28: ⑤ 시장과열·단기 트리거 | E28: 높음 | F28: 보존 | G28: 시점/누출 | H28: 미정
A29: V028 | B29: 아파트 월세통합가격지수 | C29: ⑤ 시장과열·단기 트리거 | D29: 유사/중복군_월세통합가격지수 | E29: 높음 | F29: 보존 | G29: 중복성, 시점/누출 | H29: 미정
A30: V029 | B30: 아파트 전월세통합지수 | C30: ③ 금융여건·상대가격 | E30: 낮음 | F30: 보존 | G30: 자치구 미지원 | H30: 미정
A31: V030 | B31: 아파트 지역별 전월세전환율 | C31: ③ 금융여건·상대가격 | D31: 유사/중복군_전월세전환율 | E31: 낮음 | F31: 보존 | G31: 중복성 | H31: 미정
A32: V031 | B32: 아파트 매매수급동향지수 | C32: ③ 금융여건·상대가격 | E32: 낮음 | F32: 보존 | G32: 자치구 미지원 | H32: 미정
A33: V032 | B33: 아파트 전세수급동향지수 | C33: ④ 임대시장 수급·전환 구조 | E33: 낮음 | F33: 보존 | G33: 자치구 미지원 | H33: 미정
A34: V033 | B34: 아파트 월세수급동향지수 | C34: ④ 임대시장 수급·전환 구조 | E34: 낮음 | F34: 보존 | G34: 자치구 미지원 | H34: 미정
A35: V034 | B35: 구(舊) 수급동향 통합지수 | C35: ④ 임대시장 수급·전환 구조 | E35: 낮음 | F35: 보존 | G35: 자치구 미지원 | H35: 미정
A36: V035 | B36: 행정구역별 아파트 거래현황(동·호수, 면적) | C36: ④ 임대시장 수급·전환 구조 | E36: 낮음 | F36: 보존 | G36: 기본 검토 | H36: 미정
A37: V036 | B37: 행정구역별 아파트 매매거래현황(동·호수, 면적) | C37: ③ 금융여건·상대가격 | E37: 낮음 | F37: 보존 | G37: 기본 검토 | H37: 미정
A38: V037 | B38: 주택시장 소비심리지수 | C38: ⑤ 시장과열·단기 트리거 | E38: 중간 | F38: 보존 | G38: 자치구 미지원 | H38: 미정
A39: V038 | B39: 미분양주택현황 | C39: ② 주택공급·재고 여건 | E39: 낮음 | F39: 보존 | G39: 기본 검토 | H39: 미정
A40: V039 | B40: 주민등록 세대수 | C40: ① 임차수요 압력 | D40: 유사/중복군_주민등록세대수 | E40: 낮음 | F40: 보존 | G40: 중복성 | H40: 미정
A41: V040 | B41: 아파트 주택건설 인허가 실적 | C41: ② 주택공급·재고 여건 | E41: 낮음 | F41: 보존 | G41: 자치구 미지원 | H41: 미정
...

Sheet Research_Notes
A1: 항목 | B1: 보완 내용 | C1: 근거 URL
A2: 임대주택공급현황 / 임대주택건설공급현황 | B2: KOSIS 공식 Q&A에 따르면 임대주택통계는 국토교통부가 시·도 및 공공기관 자료를 취합·공표하며, 2012~2019와 2020년 이후는 법령 개정 등에 따라 세부 분류기준이 달라짐. 변수는 삭제하지 않고 구조변화 관리 필요. | C2: https://kosis.kr/civilComplaint/qnaDetail.do?boardIdx=21575
A3: 실시간 조기경보 공통 원칙 | B3: 기준기간(reference period)과 실제 발표/가용시점(available date)을 분리해 관리. 저빈도 자료를 월별로 확장할 경우 발표 이전 월에는 값을 채우지 않음. | C3: 프로젝트 내 데이터사전 및 한국은행 조기경보 연구 원칙
